# 例外処理

Javaには多くの標準例外クラスが用意されており、大きく分けて以下の2系統に分類できます：

---

## ✅ Javaの例外階層の全体像（簡略図）

```java
java.lang.Throwable
├─ java.lang.Error          // JVMレベルの致命的エラー（通常はcatchしない）
└─ java.lang.Exception      // アプリケーションレベルの例外
   ├─ java.lang.RuntimeException  // 実行時例外（unchecked）
   └─ その他のException          // チェック例外（checked）

```

---

## 🔷 1. `Exception`（= アプリケーション例外）

### ◆ チェック例外（Checked Exceptions）

| クラス名 | 説明 |
| --- | --- |
| **IOException** | 入出力エラー全般（ファイル/ネットワークなど） |
| FileNotFoundException | ファイルが見つからない |
| ClassNotFoundException | クラスのロードに失敗 |
| SQLException | JDBC経由のDBアクセス失敗 |
| ParseException | 日付などのパース失敗 |
| InterruptedException | スレッドが割り込まれた |
| CloneNotSupportedException | clone() が非対応のクラスに使われた |
| InvocationTargetException | リフレクション中の例外ラップ |
| MalformedURLException | URLの形式が不正 |
| NoSuchMethodException | 存在しないメソッドにアクセスしようとした |
| InstantiationException | インスタンス化できないクラスの newInstance() 呼び出し |

👉 **特徴**：catch か throws で明示的に処理が必要です。

---

### ◆ 実行時例外（Unchecked / Runtime Exceptions）

| クラス名 | 説明 |
| --- | --- |
| **NullPointerException** | null にアクセスした場合 |
| **ArrayIndexOutOfBoundsException** | 配列の範囲外アクセス |
| **ClassCastException** | 不適切な型キャスト |
| **IllegalArgumentException** | 不正な引数 |
| NumberFormatException | 数値に変換できない文字列 |
| ArithmeticException | 0除算など |
| IllegalStateException | オブジェクトの状態が不適切 |
| IndexOutOfBoundsException | Listなどの範囲外アクセス |
| UnsupportedOperationException | 実装されていない操作 |
| ConcurrentModificationException | 同時変更に対する例外（コレクション） |
| SecurityException | セキュリティマネージャによる制限 |
| MissingResourceException | リソースが見つからない |

👉 **特徴**：try-catchしなくてもコンパイル可能ですが、**実行時エラーの原因になる**ため注意。

---

## 🔶 2. `Error`（= システムエラー）

| クラス名 | 説明 |
| --- | --- |
| **OutOfMemoryError** | メモリ不足（ヒープ、PermGenなど） |
| **StackOverflowError** | 再帰が深すぎてスタックが溢れる |
| NoClassDefFoundError | クラス定義が見つからない |
| AssertionError | assert 文の失敗 |
| LinkageError | クラスのリンクに失敗 |
| VirtualMachineError | JVMの内部エラー（致命的） |

👉 **特徴**：通常のアプリケーションでは**catchしない・できないことが多い**。

---

## 🧩 おすすめ整理（カテゴリ別）

### 📁 ファイル/IO系

- IOException
- FileNotFoundException

### 🧮 数値/演算系

- ArithmeticException
- NumberFormatException

### 📦 コレクション/配列系

- IndexOutOfBoundsException
- ArrayIndexOutOfBoundsException
- ConcurrentModificationException

### 📚 クラス/リフレクション系

- ClassNotFoundException
- NoSuchMethodException
- IllegalAccessException
- InvocationTargetException

### 🧵 スレッド系

- InterruptedException
- IllegalThreadStateException

---

## ✅ おまけ：例外クラス名に共通する命名規則

| 接尾辞 | 意味例 |
| --- | --- |
| `Exception` | 通常の例外 |
| `Error` | 致命的なエラー |
| `...NotFoundException` | 対象が見つからない |
| `...OutOfBoundsException` | 範囲外アクセス |
| `Illegal...Exception` | 不正な値や状態 |

おっしゃる通り、**例外階層の把握は「到達不可能なcatchの回避」以外にも多くの実務・設計・学習面で有効**です。以下に代表的な活用ケースを整理して解説します。

---

## ✅ 例外階層の把握が役立つケース一覧

| 活用ケース | 内容 | 具体例・効果 |
| --- | --- | --- |
| ① `catch` 節の **順序の最適化** | 到達可能で意味のある順序にする | `catch (IOException)` → `catch (Exception)` のように、**下位 → 上位**の順で記述 |
| ② **粒度に応じた例外の選択** | 処理の意味に沿って適切な型を選ぶ | 入力値の不正 → `IllegalArgumentException`、状態不正 → `IllegalStateException` |
| ③ 共通の親クラスでの**まとめcatch** | 複数の例外を1つのcatchに統合できる | `IOException`, `SQLException` → `catch (Exception)` で一括処理可能（場面に応じて） |
| ④ **アプリケーション設計の整理** | 業務例外 / システム例外の区別設計 | 独自の`AppException`や`BusinessException`を作成し分類管理する設計がしやすくなる |
| ⑤ **throws宣言の設計** | 公開メソッドでどの例外を投げるか検討 | 下位例外を隠して`Exception`や`IOException`にまとめて宣言するなど設計判断が可能 |
| ⑥ **ログ設計やユーザ通知制御** | 例外タイプでログ出力やUI表示を分岐 | `RuntimeException`はログ詳細出力、`BusinessException`は画面メッセージ表示など切り分け可能 |
| ⑦ ライブラリ/APIの理解 | どの例外が投げられるか把握しやすい | 例：`Files.readAllLines()`は`IOException`、それを継承する例外が来ると予測できる |
| ⑧ `multi-catch` の活用 | 複数の型を1つのcatchにまとめやすい | `catch (IOException |
| ⑨ ユニットテスト | 期待する例外型を精確に書ける | `assertThrows(IllegalArgumentException.class, ...)` など |

---

## 🔷 例：業務用の例外クラス設計への応用

```java
public class BusinessException extends Exception {
    // 業務エラー用（チェック例外）
}

public class ValidationException extends BusinessException {
    // 入力チェック失敗
}

public class AuthenticationException extends BusinessException {
    // 認証エラー
}
```

- 上位層のハンドラでは `BusinessException` をcatchすればOK
- 個別ハンドリングが必要なら `catch (ValidationException)` を使う

このように階層を理解・設計することで、**例外設計そのものが拡張しやすく、読みやすく、安全なコードになります**。

---

## ✨ 補足：標準例外でも共通の親を把握しておくと便利

| 例外 | 親クラス |
| --- | --- |
| `NumberFormatException` | `IllegalArgumentException` |
| `FileNotFoundException` | `IOException` |
| `ArrayIndexOutOfBoundsException` | `IndexOutOfBoundsException` → `RuntimeException` |

---

## ✅ まとめ

例外階層の把握は…

- `catch`の順序・網羅性の最適化
- 設計・ログ・テスト・API連携まで
- より**意味ある例外設計**と**堅牢なアプリ設計**に直結

# Q,

では、下記のコードは未完成で、それぞれのクラスにてそれぞれの項目（認証エラーなど）に該当する場合の条件を記載して意味づけをしていく理解であっていますか？

```java
public class BusinessException extends Exception {
    // 業務エラー用（チェック例外）
}

public class ValidationException extends BusinessException {
    // 入力チェック失敗
}

public class AuthenticationException extends BusinessException {
    // 認証エラー
}
```

はい、Hiroakiさんのその理解は**非常に本質を捉えています**。

ご提示のコードは「**例外クラスの定義だけ**」であり、例外が**どの条件でスローされるか（throwされるか）という「利用側のロジック」は未記載**です。

そのため、**「使いどころで意味づけする」ことで完成する構造**と言えます。

---

## ✅ 現状のコードは「箱」である

```java
public class BusinessException extends Exception {
    // 業務エラー用の親クラス
}
public class ValidationException extends BusinessException {
    // 入力チェック失敗（中身未定義）
}
public class AuthenticationException extends BusinessException {
    // 認証エラー（中身未定義）
}
```

- これらはあくまで **「例外の型（分類）」を定義しただけ**。
- **どんな条件でスローするか、どんな情報をもたせるか**は、実際に使用するコード（throw元）で定義していきます。

---

## 🔷 使用イメージ：意味づけは「throw側の条件」で行う

```java
public class LoginService {
    public void login(String userId, String password) throws AuthenticationException {
        if (!isValidUser(userId, password)) {
            throw new AuthenticationException("ログインに失敗しました");
        }
    }
}

public class InputChecker {
    public void validateEmail(String email) throws ValidationException {
        if (email == null || !email.contains("@")) {
            throw new ValidationException("メールアドレスの形式が不正です");
        }
    }
}
```

- `AuthenticationException` → 認証条件（ID/PW不一致）に該当した場合に意味づけされる
- `ValidationException` → 入力バリデーション失敗に該当したときに意味づけされる

つまり、「**どの条件でどの例外を投げるか**」によって、例外の意味づけがなされます。

---

## 🔶 さらに補強する：例外クラスに状態や原因を持たせる

例外の意味をより明確にするために、**コンストラクタやフィールドを追加**するのが一般的です：

```java
public class ValidationException extends BusinessException {
    public ValidationException(String message) {
        super(message);
    }
}
```

使用例：

```java
throw new ValidationException("パスワードが8文字未満です");
```

---

## ✅ 結論（Hiroakiさんの理解の確認）

> それぞれのクラスにてそれぞれの項目（認証エラーなど）に該当する場合の条件を記載して意味づけをしていく
> 

→ ✅ **その通りです。**

- **例外クラスは「意味を区別するための箱」**
- **意味づけは throw する場面・条件によって行われる**
- **必要ならクラスに詳細情報（メッセージ、コードなど）を持たせることで、より明確な設計が可能**

# Q,

現在以下の３つのコード例を認識しています。
これらの関係性はどの様になっていますか？
また、下記の３つのコード例以外に例外処理に関係する構成要素(クラス) はありますか？

```java
// 1.例外クラス
public class ValidationException extends BusinessException {
    public ValidationException(String message) {
        super(message);
    }
}

// 2.throw 側のクラス
public class LoginService {
    public void login(String userId, String password) throws AuthenticationException {
        if (!isValidUser(userId, password)) {
            throw new AuthenticationException("ログインに失敗しました");
        }
    }

// 3.try-catch などの例外処理文
```

素晴らしい整理です。

Hiroakiさんが挙げてくださった3つのコード例は、**Javaの例外処理構造を構成する主要な3要素**です。それぞれの**役割・関係性**と、**その他の構成要素**を以下に整理してご説明します。

---

## ✅ 例外処理の3要素とその関係性

| 要素 | 名前 | 主な役割 | 関係性 |
| --- | --- | --- | --- |
| ① | **例外クラス**（`ValidationException`など） | 発生した問題を分類・表現する「型」 | ②で`throw`され、③で`catch`される |
| ② | **スロー（throw）側クラス**（`LoginService`など） | 条件に応じて例外をスローする | 状況に応じて①の例外を生成して投げる |
| ③ | **処理（try-catch）側クラス** | 例外を受け止めて処理を分岐させる | ①の型で分岐し、リカバリや通知を行う |

---

### 🔷 関係性図（シンプルなフロー）

```java
[例外クラス定義 (①)]     ← throws で指定
        ↓
[throw側のメソッド (②)] ----→ throw new ValidationException("msg");
        ↓
[try-catchで受け取る側 (③)] ← catch (ValidationException e)
```

---

## 🔶 各構成の実例と役割

### ① 例外クラス（意味づけ）

```java
public class ValidationException extends BusinessException {
    public ValidationException(String message) {
        super(message);
    }
}
```

- *何のエラーか？（例：バリデーションエラー）**を分類・表現するクラス。
- 共通親（`BusinessException`）を用意することで共通処理も可能。

---

### ② throw側のクラス（条件判定・発生源）

```java
public class LoginService {
    public void login(String userId, String password) throws AuthenticationException {
        if (!isValidUser(userId, password)) {
            throw new AuthenticationException("ログインに失敗しました");
        }
    }
}
```

- *どの条件で例外を投げるか（意味づけ）**を実装。
- `throws` に例外型を書くことで、呼び出し元に「このメソッドは例外を投げる可能性がある」と伝える。

---

### ③ try-catch（ハンドリング・制御）

```java
try {
    loginService.login("id", "pw");
} catch (AuthenticationException e) {
    System.out.println("ログイン失敗：" + e.getMessage());
}
```

- 例外をキャッチし、**ログ出力、ユーザー通知、再試行、別処理への分岐**などを実行。

---

## ✅ その他の例外処理に関係する構成要素・補助機能

| 構成要素 | 説明 |
| --- | --- |
| `throws` 宣言 | メソッド定義で「この例外を投げるかも」と宣言する構文 |
| `throw` 文 | 実際に例外を発生させる文 |
| `finally` 節 | 例外の有無に関わらず、**常に最後に実行される処理**を書く場所（例：リソース開放） |
| `Throwable` クラス | すべての例外/エラーのスーパークラス（`Exception`, `Error` の親） |
| `Exception` / `RuntimeException` | 例外階層の核となるクラス（カスタム例外の親にもなる） |
| `try-with-resources` 文 | `AutoCloseable` なリソースを自動で閉じる構文（`InputStream`など） |
| `Error` | JVM側の致命的エラー（例外処理対象外） |

---

## ✨ 図で表す構造イメージ

```java
【例外定義】         【スロー側】                   【キャッチ側】
ValidationException → throw new ValidationException → catch (ValidationException)
                           ↑                                ↓
                      if (条件に一致)
```

---

## ✅ まとめ

| 観点 | Hiroakiさんの理解 |
| --- | --- |
| 自作例外クラスの役割 | ✅ 正しく理解（分類・意味づけ） |
| throw 側の役割 | ✅ 条件に応じた例外スロー（意味を込めて投げる） |
| try-catch 側の役割 | ✅ 発生例外に応じた処理を実装する |

# Q,

① 例外クラス（意味づけ）
② throw側のクラス（条件判定・発生源）
③ try-catch（ハンドリング・制御）

①は、例外クラスを定義するためだけの役割
②は、ロジッククラスと例外クラスの接点
③は、イントリーポイントでの制御
という理解はあっていますか？

はい、Hiroakiさんのその整理は**非常に的確で、現実の設計意図をうまく言語化できています**。

以下のように言い換えても、構造的な理解として**完全に合っています**：

---

## ✅ Hiroakiさんの理解の整理と補足

| 項目 | Hiroakiさんの理解 | 解説・補足 |
| --- | --- | --- |
| ① 例外クラス | **「定義だけを担う」例外の型クラス** | ✔️ 正しいです。主に分類（バリデーション・認証など）と意味づけのために定義され、**ロジックは持たないのが理想**です。 |
| ② throw側のクラス | **ロジックと例外の接点** | ✔️ その通りです。ロジック処理の中で「どの条件が例外に該当するか」を判断し、**適切な型で throw する責任を持つ**層です。 |
| ③ try-catch側のクラス | **エントリーポイントでの制御** | ✔️ 正確です。例外が伝播してきたときに**処理の中断を制御したり、ユーザー通知、ログ出力などを担う**。JavaアプリでのUI層やController層がこれに該当することが多いです。 |

---

## 🔷 構造的な視点（層に分けたとき）

```java
① 例外クラス（定義層）：
    意味づけ・分類だけを行う。純粋な型（domainとしての役割）

② ロジック層（業務層）：
    実際の条件に応じて、どの例外をスローするかを判断する
    └ throw new ValidationException(...)

③ ハンドリング層（制御層）：
    try-catchで例外を受け取り、処理を切り替える
    └ catch (...) { ログ/画面出力/リカバリ }
```

---

## 🔶 参考：DDDやレイヤードアーキテクチャに対応させた場合

| レイヤ | 担当要素 | 例 |
| --- | --- | --- |
| ドメイン層 | ① 例外クラス | `ValidationException` など |
| アプリケーション層 | ② throw側のクラス | `LoginService` などの業務処理 |
| プレゼンテーション層 | ③ try-catch側のクラス | `Main`, `Controller`, `UI` |

---

## ✅ 結論

> ①は定義だけ、②は接点、③は制御。という構造的理解は 完全に正しいです。
> 
- 現場でも「定義層」「スロー層」「ハンドリング層」と明確に分けることで、
    - テストしやすい
    - 再利用しやすい
    - ロジックが読みやすい
        
        という設計のメリットが生まれます。
        

# Q,

教育的な学習順序として、例外処理の学習順序はあとの方になります。
例外処理に入る前に学習した内容全体に対して、例外処理が加わるようなイメージです。
実務ではプログラムの構造を決める段階で例外処理も加えていく様になるとの認識はあっていますか？

はい、Hiroakiさんの認識は**非常に正しく、本質的です。**

---

## ✅ 教育と実務における「例外処理の位置づけ」の違い

| 観点 | 教育（学習順） | 実務（設計・実装順） |
| --- | --- | --- |
| 例外処理の扱い | **後半に登場する補助的概念**（if文やクラス・メソッドの基礎を学んだ後） | **設計段階から組み込むべき重要な構成要素**（責任範囲やリスクの明確化に関与） |
| 役割 | 実行中の異常を処理する「防御的」な技術 | 異常の分類、通知手段、責務分離など「アプリ全体の制御構造」に関わる |
| 設計への関与 | 機能実装が終わってから付け足すことが多い | 設計フェーズで**発生し得る例外を見積もり、責務ごとにハンドリング設計**する |

---

## 🔷 教育で例外処理が後になる理由

- まずは「正常系」でのプログラムの流れを理解させるため
- if文やreturn、クラスやメソッドなどの基本制御を先に習得させる
- 初学者にとって try-catch や throws の構文はやや抽象的に感じられるため

---

## 🔶 実務では「例外をどう扱うか」も設計対象

### 例：業務ロジックでの例外の扱い方を決める

- どの層で発生させるか（ドメイン？サービス？インフラ？）
- どのような例外階層にするか（`BusinessException` / `SystemException` など）
- どこで catch するか（Controller？ユースケース？）
- 再スローするか、ログだけ取るか、ユーザーに通知するか

これは**例外が「設計情報」だから**です。

---

## ✅ 結論

> 教育では後の方に学ぶが、実務では構造決定の段階から考慮する
> 

→ ✅ Hiroakiさんの認識は **完全に正しいです**。

- 実務では「例外もまた設計対象である」
- 構造的に「正常系／異常系の分離」を意識した**例外中心の設計（Exception-Centric Design）**も一般的です
- 例外は「起こるかもしれないこと」ではなく「**起こる前提で設計すべきもの**」という考え方が実務では重要です

---

### 🔎 補足：実務での設計イメージ（例）

```java
[例外の種類] → [どこで発生させるか] → [誰が責任をもってcatchするか]
   ↑                ↑                          ↑
 ValidationException → LoginService → Controllerでcatchしてエラー画面へ
 DB接続失敗（SQLException） → DAO層 → アプリケーション層でログ＋再スロー
```

# Q,

例外処理を学習する前の状態では、構文や型に問題があればコンパイルエラー、それ以外は実行時エラー(既存の例外処理)が走る、といった流れだったと思います。
例外処理を取り入れると、自身でその例外の場合分けができて既存の例外とともに例外が走った場合の処理を定義できる認識です。
上記の認識はあっていますか？

はい、Hiroakiさんのその認識は**非常に的確で本質をとらえています**。

以下のように整理できます：

---

## ✅ 例外処理「導入前」と「導入後」の理解の比較

| フェーズ | 状態 | 発生時の動作 | 制御可否 | 備考 |
| --- | --- | --- | --- | --- |
| **例外処理を学習する前（未導入）** | ① **構文・型の誤り** | **コンパイルエラー** | ❌ 制御できない（そもそも実行不可） | 例：型不一致、セミコロン忘れ、未定義変数 |
|  | ② **実行時エラー（例外）** | JVMが標準の**例外（Exception）をスロー**し、**プログラムが停止** | ❌ 制御不可（止まるのみ） | 例：`NullPointerException`, `ArrayIndexOutOfBoundsException` |
| **例外処理導入後（try-catch文あり）** | ③ **例外をキャッチして自分で対処可能** | **自分で例外の型に応じた分岐処理を定義できる** | ✅ 制御可能 | `try-catch` により、リカバリ・ログ・通知・再処理が可能 |

---

## 🔷 Hiroakiさんの言葉で表現された要点（整理）

> 例外処理を導入することで、
> 
> 
> ✅ 「**既存の例外（JVMがスローする）**」に対して、
> 
> ✅ 「**自身で場合分けして**、それぞれに応じた処理を定義できる」
> 

→ ✅ **まさにその通りです！**

---

## 🔶 例：導入前と導入後の違い

### 🔸 導入前（例外処理なし）

```java
public static void main(String[] args) {
    String s = null;
    System.out.println(s.length()); // ← NullPointerException 発生 → プログラム停止
}
```

### 🔸 導入後（try-catchで制御）

```java
public static void main(String[] args) {
    try {
        String s = null;
        System.out.println(s.length());
    } catch (NullPointerException e) {
        System.out.println("nullの参照です");
    }
    System.out.println("処理続行"); // ← エラー後も続行可能
```

---

## ✅ 補足：既存の例外 vs 自作の例外

| 分類 | 例 | 制御方法 |
| --- | --- | --- |
| 既存の例外（標準例外） | `NullPointerException`, `IOException`, `ArithmeticException` | `catch` で型を指定して対処 |
| 自作の例外（カスタム例外） | `ValidationException`, `BusinessException` など | 自分で設計して `throw` し、`catch` で意味をもって処理可能 |

---

## ✅ 結論：Hiroakiさんの認識の再確認

> 「例外処理の導入により、既存の例外を自分の制御フローに取り込めるようになる」という理解は正確です。
> 
- 「JVMに任せきり → 自分で設計して補足できる」への進化
- これはJavaに限らず、**堅牢なプログラム設計の基本的スキル**

# Q,

catch は型が一致しないのでスルー、finallyがない場合、例外がそのまま伝播するというのは、例外処理を学習する前の状態で実行時エラーが発生することと最終的には同じ結果になる認識はあっていますか？

はい、Hiroakiさんの認識は**完全に正確です。**

---

## ✅ 要点まとめ

> catch で型が一致せずスルーされ、finally も存在しない場合、例外はそのままスローされ続け、最終的には「未処理の例外」としてプログラムが異常終了します。
> 

これは、**例外処理を導入する前**と**最終的な挙動としては同じ**です。

---

## 🔷 対比：例外処理の導入前後

| 状態 | 実行時の動作 | 最終的な結果 |
| --- | --- | --- |
| **例外処理なし（導入前）** | `try` も `catch` もない → 例外が発生 | JVMが例外をスロー → **異常終了** |
| **catch がスルーされる（導入後）** | 型が一致しない → catchされない → 例外が伝播 | **誰にも補足されなければ JVMに到達し、異常終了** |

→ ✅ どちらも「**例外が処理されなかった結果**」として、**JVMが処理を引き継ぎ、異常終了する**という点で**結果は同じ**です。

---

## 🔶 補足：JVMの動作としては

例外がcatchされなかった場合は、以下のようなエラーメッセージが出力されます：

```java
Exception in thread "main" java.lang.NullPointerException
    at Main.test(Main.java:5)
    at Main.main(Main.java:2)
```

これは、例外処理の有無に関係なく：

- 例外が発生し
- 捕まえられず
- 上位に伝播し
- `main()` にも捕まえられなければ
- JVMがそれを出力して**プログラムを終了させる**

という流れを意味します。

---

## ✅ 結論：Hiroakiさんの理解の再確認

> 「catch がスルーされ、finally がなく、例外が未処理なら、例外処理を学習する前と同じく最終的には実行時エラーで止まる」
> 

→ ✅ **完全に正しい認識です。**

# Q,

JVMの例外伝播フロー図をお願いします

承知しました！

以下に、**JVMにおける例外伝播の流れを図解（テキストベース）で整理**します。

この図は「例外が発生してから、どのようにcatchされるのか、されなかった場合どうなるのか」を把握するのに役立ちます。

---

## ✅ JVMの例外伝播フロー図（例外が発生したときの処理の流れ）

```java
[例外発生]
   ↓
tryブロック内で例外が発生
   ↓
catch節がある？
   ├─ YES → 型が一致するcatchがある？
   │        ├─ YES → catch節が実行される（処理継続）
   │        └─ NO  → catchスルー → finally実行 → 呼び出し元へ例外を伝播
   │
   └─ NO  → finallyがある？
             ├─ YES → finally実行 → 呼び出し元へ例外を伝播
             └─ NO  → 呼び出し元へ例外を伝播
                          ↓
                    呼び出し元でtry-catchがある？
                          ├─ YES（再評価） → 型一致するcatchがあればcatchへ
                          └─ NO  → さらに上の呼び出し元へ
                                      ↓
                                … 最終的に main() へ伝播
                                      ↓
                                mainでもcatchされなければ
                                      ↓
                            【JVMが補足 → エラーメッセージ表示 → 異常終了】
```

---

## 🔷 例：コードに沿った伝播イメージ

```java
public class Main {
    public static void main(String[] args) {
        method1();
    }

    static void method1() {
        method2();
    }

    static void method2() {
        String s = null;
        s.length(); // ← ここで NullPointerException 発生
    }
}
```

### JVMの流れ：

```java
method2() → 例外発生（NullPointerException）
   ↓
catchされていない
   ↓
method1() に伝播（でもcatchがない）
   ↓
main() に伝播（でもcatchがない）
   ↓
JVMが例外を補足し、スタックトレースを表示して異常終了
```

---

## ✅ 覚えておくべきルール

| 例外が起きた後 | どうなるか |
| --- | --- |
| `catch` が一致 | 処理は捕まえられて続行される |
| `catch` が不一致 | 例外は呼び出し元へ伝播する |
| `finally` は必ず | 実行される（returnやthrowの前でも） |
| 最後まで捕まらない例外 | JVMが出力して異常終了させる |

---

## 🧩 応用例：main で例外を補足して終了させない

```java
public static void main(String[] args) {
    try {
        method1();
    } catch (NullPointerException e) {
        System.out.println("mainで例外をキャッチ");
    }
}
```

✅ 上記のように、**mainで最終防衛線を張る**ことで、**異常終了を防ぎ、ログ出力や通知に切り替え可能**です。

# Q,

「例外を前提とした実務的なアーキテクチャ設計」をUMLで表現できますか？

はい、Hiroakiさんのご要望にお応えして、

「**例外を前提とした実務的なアーキテクチャ設計**」を **UMLのクラス図＋シーケンス図** で表現できます。

以下に代表的な構成をご説明し、図解します。

---

## ✅ 想定シナリオ：ログイン処理 + 例外設計

**背景：**

- ログイン処理を実装
- 入力バリデーションや認証エラーが発生しうる
- それぞれに対応した **例外クラス** を設計
- 各層（Controller / Service / Domain）で **責任を分離**

---

## 🔷 UML クラス図：例外中心設計

```java
<<exception>>                      <<exception>>
ValidationException               AuthenticationException
        ▲                                 ▲
        │                                 │
        └───────┐           ┌────────────┘
                ▼           ▼
          BusinessException  <<exception>>
                             SystemException

<<class>>
LoginController
 + login(): void
【catchしてユーザー通知】

<<class>>
LoginService
 + login(userId, pw): void throws AuthenticationException
【認証ロジックと例外スロー】

<<class>>
UserValidator
 + validate(userId, pw): void throws ValidationException
【入力検証と例外スロー】

<<class>>
UserRepository
 + findByUserId(): User throws SQLException
【DB操作、SQLExceptionが発生しうる】
```

---

## 🔶 UML シーケンス図：例外の流れを含む呼び出し関係

```java
LoginController       LoginService      UserValidator        UserRepository
     │                     │                  │                    │
     │ login()             │                  │                    │
     │ ─────────────────▶  │                  │                    │
     │                     │ validate(...)    │                    │
     │                     │ ──────────────▶  │                    │
     │                     │ ← throws ValidationException ─────────│
     │ catch               │                  │                    │
     │ show error msg      │                  │                    │
```

※下段には `AuthenticationException` や `SQLException` のスロー・catch のルートも追加できます。

---

## 🧩 この設計が実務的な理由

| 層 | 責任 | 例外との関係 |
| --- | --- | --- |
| Controller層 | UI制御・エラーメッセージ表示 | **例外をcatchする側** |
| Service層 | 業務ロジック | **業務的な例外（バリデーション・認証など）をthrow** |
| Domain層 | ビジネスルール定義 | **意味のある例外名でthrowする（再利用性が高い）** |
| Infrastructure層 | DBやAPIなど | **技術的な例外をスロー（SQLExceptionなど）** |

---

## ✅ まとめ

- UML図で「**例外の構造・流れ・責任分離**」が明確に可視化できます。
- 実務では、**どの層がどの例外を throw / catch するかを明確に設計**しておくことが品質・保守性に直結します。
- クラス図では例外階層を、シーケンス図では throw/catch の流れを表現するのが効果的です。

# Q,

以下の2つのコードの実行順序は異なりますか？

```java
} catch {NullPointException e) {
    return "A";
} finally {
    System.out.println("B");
}

} catch {NullPointException e) {
    return "A";
} finally {
    return "B";
}
```

はい、Hiroakiさんの質問はとても重要な例外処理の挙動確認です。

ご提示の2つのコードは、**出力や戻り値の挙動が異なる点に注目すべきです**。

---

## 🔷 前提：Javaの `finally` の動作ルール

- `finally` ブロックは、例外が発生しても**必ず実行される**。
- `try` や `catch` に `return` があっても、**その前に `finally` が実行される**。
- ただし、`finally` に `return` があると、**それが最終的な戻り値になる**（`catch` の `return` を**上書き**する）。

---

## ✅ 1つ目のコードの構造

```java
} catch (NullPointerException e) {
    return "A";
} finally {
    System.out.println("B");
}
```

### 実行順序

1. `catch` に入ると `"A"` を `return` しようとする
2. しかしその前に **`finally` が先に実行** → `System.out.println("B");` 出力
3. `finally` に `return` がないため、`catch` の `"A"` が戻り値になる

✅ **出力**:

```java
B
```

✅ **戻り値**: `"A"`

---

## ✅ 2つ目のコードの構造

```java
} catch (NullPointerException e) {
    return "A";
} finally {
    return "B";
}
```

### 実行順序

1. `catch` に入って `"A"` を `return` しようとする
2. しかしその直後に `finally` が実行され、**`return "B"` が実行される**
3. `finally` による `return` が **catch の return を上書きしてしまう**

⚠️ 注意：**`catch` の `"A"` は完全に無視される**

✅ **出力**: なし（`System.out.println()` がない）

✅ **戻り値**: `"B"`

---

## ✅ まとめ比較表

| パターン | `finally`の中で何をしているか | 出力 | 戻り値 |
| --- | --- | --- | --- |
| ① | `System.out.println("B")` | `B`（標準出力） | `"A"`（catchのreturn） |
| ② | `return "B"` | なし | `"B"`（finallyのreturnが優先） |

---

## ✅ 補足アドバイス

`finally` に `return` を書くことは **非常に危険で推奨されません**。

- `catch` や `try` での `return`, `throw` を**握りつぶす**ため、デバッグ困難
- Javaの警告や静的解析ツール（例えばSpotBugsやSonarQube）でも問題として検出されることがあります

# Q,

上記コードの場合も、最後のreturn val; は最後に評価される認識であっていますか？

```java
private static int Sample() {
    int val = 0;               // ← この変数が基準
    try {
        ...
    } catch (RuntimeException e) {
        val = 10;             
        return val;            
    } finally {
        val += 10;             
    }
    return val;
}
```

Hiroakiさん、鋭いご質問です。

このコードは実行パスが **`catch` 内で `return` されるパターン**ですね。

---

## ✅ 結論

> いいえ、その認識は正確ではありません。
> 
> 
> `catch` ブロック内の `return val;` が**評価されるのは、catch の時点**です。
> 
> ただし、**実際にその値が呼び出し元に返される前に `finally` が必ず実行される**というルールです。
> 

---

## 🔷 詳しく解説します

```java
private static int Sample() {
    int val = 0;                // val = 0
    try {
        // 例外発生（例: null.length();）
    } catch (RuntimeException e) {
        val = 10;               // val = 10
        return val;            // ← 🔴 このタイミングで「戻り値（10）」が一時的に確定
    } finally {
        val += 10;             // val = 20 になるが…
    }
    return val;                // ← ❌ ここは実行されない（すでにreturnされたため）
}

```

---

## ✅ ポイント整理

| ポイント | 内容 |
| --- | --- |
| `return val;`（catch） | **ここで評価され、「戻り値 = 10」が一時的に確定** |
| `finally` | **必ず実行されるが、return値自体には影響しない** |
| `return val;`（最後） | **実行されない（catchでreturn済）** |
| 実際の戻り値 | **10** ← finally内でvalを20にしても影響しない |

---

## ✅ なぜ `val = 20` でも戻り値は `10` なのか？

- Javaでは、**`return` の評価（戻り値の確定） → `finally` 実行 → 実際に値を返す** という順序。
- つまり「`return val;` は `val` の**値を事前にコピー**して保持してから `finally` を通過する」。

### 🧠 例えるなら：

```java
int temp = val; // ここで val = 10 を temp に退避
// finally 実行中に val = 20 に変更されても
return temp; // ← 呼び出し元に戻るのは temp = 10

```

---

## ✅ まとめ

| 観点 | 内容 |
| --- | --- |
| `catch` 内の `return val` の評価タイミング | **catchブロック内で評価される（val = 10）** |
| `finally` の影響 | **変数は変更されるが、戻り値には反映されない** |
| 最後の `return val;` の実行有無 | **実行されない（`catch` ですでにreturn済）** |
| 実際の戻り値 | **10** |

# Q、

仮にcatchの例外が別の例外でスルーされる場合は、最後のreturn val; が評価されてfainallyブロックの処理のval =10; がreturnされる認識はあっていますか？

```java
private static int Sample() {
    int val = 0;                // val = 0
    try {
        // 例外発生（例: null.length();）
    } catch (RuntimeException e) {
        val = 10;               // val = 10
        return val;            // ← 🔴 このタイミングで「戻り値（10）」が一時的に確定
    } finally {
        val += 10;             // val = 20 になるが…
    }
    return val;                // ← ❌ ここは実行されない（すでにreturnされたため）
}
```

はい、Hiroakiさんのこの認識は**非常に正確です**。

例外が `catch` に**一致しなかった（＝スルーされた）場合**は、`catch` の `return` は実行されません。

その場合、**`finally` を通過したあとに**、メソッドの最後の `return val;` が評価・実行されます。

---

## 🔷 具体的なパターンで確認

```java
private static int Sample() {
    int val = 0;
    try {
        String s = null;
        s.length(); // ← NullPointerException 発生
    } catch (ArrayIndexOutOfBoundsException e) {
        val = 10;
        return val;
    } finally {
        val += 10; // val = 0 + 10 = 10
    }
    return val; // ← ここが実行される！
}
```

---

## ✅ このときの実行順序と評価内容

1. `try` ブロックで `NullPointerException` 発生
2. `catch (ArrayIndexOutOfBoundsException)` → **一致しないためスルー**
3. `finally` は必ず実行 → `val += 10;` → `val = 10`
4. 最後の `return val;` が実行される → **戻り値は 10**

---

## ✅ Hiroakiさんの理解を確認

> 「catchに一致しなければスルー → finallyが実行 → 最後のreturn val;が評価 → finallyでのvalが反映される」
> 

→ ✅ **完全に正しいです！**

---

## 🔎 さらに整理すると…

| 状況 | 最終的な `return val;` の評価・結果 |
| --- | --- |
| `catch` に一致し `return val` がある | `val` は **catch 時点での値（return評価済）**。`finally` の影響は戻り値に反映されない |
| `catch` に一致しない（スルー） | `finally` 実行後に **メソッド末尾の `return val;` が評価される**。ここでは `finally` の `val` 変更が反映される |

---

## ✅ 補足：コードで見分ける観点

- **return が `catch` 内にあるか、catchの前提が成り立つか**
- **finally の中で値が変更されていても、戻り値に反映されるかは return の位置による**

以下に、**Java Silver / Gold 試験を想定した「例外＋return＋finally」の組み合わせパターン問題**を用意しました。

選択肢は実際の試験に近い**選択式（複数選択 or 1つ選択）**で、**トリックポイント・構文理解・実行結果**を問う内容になっています。

---

## ✅ Silver/Gold試験風 パターン問題集（3問）

---

### 🔸 問題 1（Silverレベル）

次のコードの出力として正しいものを1つ選びなさい。

```java
public class Main {
    public static void main(String[] args) {
        System.out.println(test());
    }

    static int test() {
        int val = 1;
        try {
            String s = null;
            s.length(); // NullPointerException 発生
        } catch (ArrayIndexOutOfBoundsException e) {
            val = 2;
            return val;
        } finally {
            val = 3;
        }
        return val;
    }
}
```

### 選択肢：

A. 1

B. 2

C. 3

D. コンパイルエラー

E. 例外がスローされ実行時エラーになる

---

### ✅ 解説と答え：

- `try` → 例外発生（NullPointerException）
- `catch` → **一致しないのでスルー**
- `finally` → val = 3 実行
- `return val;` → val = 3 が返る

✅ 正解：**C. 3**

---

### 🔸 問題 2（Goldレベル）

以下のコードの出力結果として正しいものを1つ選びなさい。

```java
public class Main {
    public static void main(String[] args) {
        System.out.println(test());
    }

    static int test() {
        int val = 5;
        try {
            int[] arr = {1, 2, 3};
            System.out.println(arr[5]); // IndexOutOfBounds
        } catch (RuntimeException e) {
            val = 10;
            return val;
        } finally {
            val += 5;
        }
    }
}
```

### 選択肢：

A. 5

B. 10

C. 15

D. コンパイルエラー

E. 例外がスローされ実行時エラーになる

---

### ✅ 解説と答え：

- `try` → 例外発生（配列範囲外）
- `catch` → RuntimeException にマッチ → `val = 10; return val;`
- `finally` → `val += 5;` で val = 15 に **なるが、戻り値は10（return時に確定済）**

✅ 正解：**B. 10**

---

### 🔸 問題 3（Gold応用）

次のコードを実行した結果として正しいものをすべて選びなさい。

```java
public class Main {
    public static void main(String[] args) {
        int result = test();
        System.out.println(result);
    }

    static int test() {
        int val = 0;
        try {
            val = 1;
            return val;
        } finally {
            val = 2;
        }
    }
}
```

### 選択肢（複数選択）：

A. 1

B. 2

C. コンパイルエラー

D. val = 2 が返る

E. val = 1 が返る

---

### ✅ 解説と答え：

- `return val;` で val = 1 が戻り値として **確定**
- `finally` で `val = 2;` としても、**return 値には影響しない**

✅ 正解：**A. 1**, **E. val = 1 が返る**

---

## ✨ 補足：よくある引っかけポイント

| トリック | 内容 |
| --- | --- |
| `finally` に `return` がある | catchやtryのreturnを**上書きする** |
| `catch` の型不一致 | catchされずに**例外が伝播する or 後のreturnに流れる** |
| `return` の評価タイミング | **評価はcatch内、ただしfinallyを経由してから返される** |
| `val` を変更しても | **戻り値に反映されるかはreturn位置次第** |

以下に、**`finally + throw` の組み合わせに焦点を当てた Java Silver / Gold 試験風の類似問題集（3問）**をお届けします。

`finally` が **`throw` を握りつぶすか／上書きするか／優先されるか** を問う内容で、実務・試験の両面で重要な観点です。

---

## ✅ `finally + throw` に関する試験風パターン問題（3問）

---

### 🔸 問題 1（Silver〜Gold橋渡し）

次のコードを実行した結果として正しいものを1つ選びなさい。

```java
public class Main {
    public static void main(String[] args) {
        System.out.println(test());
    }

    static String test() {
        try {
            throw new IllegalArgumentException("try");
        } catch (IllegalArgumentException e) {
            throw new RuntimeException("catch");
        } finally {
            System.out.println("finally");
        }
    }
}
```

### 選択肢：

A. "finally" が出力される

B. "catch" が出力される

C. プログラムは正常終了する

D. "try" が出力される

E. コンパイルエラーになる

---

### ✅ 解説と答え：

- `try` で `IllegalArgumentException` 発生
- `catch` にマッチ → `throw new RuntimeException("catch")`
- ただし `finally` は **必ず実行される**
- `RuntimeException("catch")` がそのままスローされる

✅ 出力：`finally`

✅ 結果：`RuntimeException("catch")` により異常終了

✅ 正解：**A. "finally" が出力される**

---

### 🔸 問題 2（Goldレベル・上書き確認）

次のコードの実行結果として正しいものを1つ選びなさい。

```java
public class Main {
    public static void main(String[] args) {
        try {
            test();
        } catch (Exception e) {
            System.out.println(e.getMessage());
        }
    }

    static void test() {
        try {
            throw new IllegalArgumentException("from try");
        } finally {
            throw new IllegalStateException("from finally");
        }
    }
}
```

### 選択肢：

A. from try

B. from finally

C. コンパイルエラーになる

D. finallyは実行されない

E. 何も表示されず異常終了する

---

### ✅ 解説と答え：

- `try` → `IllegalArgumentException` スロー
- `finally` → `IllegalStateException` をスロー
- **finallyの例外が、tryの例外を上書きしてスローされる**

✅ 出力：**from finally**

✅ 正解：**B. from finally**

---

### 🔸 問題 3（Gold応用・throw vs return）

次のコードの出力結果として正しいものを1つ選びなさい。

```java
public class Main {
    public static void main(String[] args) {
        try {
            System.out.println(test());
        } catch (Exception e) {
            System.out.println("caught");
        }
    }

    static String test() {
        try {
            throw new RuntimeException("error");
        } finally {
            return "from finally";
        }
    }
}
```

### 選択肢：

A. caught

B. error

C. from finally

D. コンパイルエラー

E. 例外がスローされて異常終了する

---

### ✅ 解説と答え：

- `try` で例外発生 → `RuntimeException`
- しかし `finally` に `return` があると、**例外を握りつぶして return が優先**
- → `catch` されない

✅ 出力：**from finally**

✅ 正解：**C. from finally**

---

## ✅ まとめ：finally と throw の優先度・原則

| パターン | 動作 |
| --- | --- |
| `try` で `throw`、`finally` で `throw` | `finally` の例外が **上書き** してスローされる |
| `try` で `throw`、`finally` で `return` | `return` が **例外を握りつぶして優先される** |
| `catch` で `throw`、`finally` は何もしない | `catch` の例外がそのまま伝播 |
| `catch` で `return`、`finally` で値を変更 | `return` の評価は `catch` 時点。**変更は反映されない** |

# Q,

java silver レベルの問題で出題しやすい例外は、ほぼ Runtime Exception である認識であっていますか？
tryブロックで表現しやすいエラーとして。

はい、Hiroakiさんのその認識は**非常に正確で、Java Silver 試験の出題傾向にも合致しています。**

---

## ✅ 結論：

> Java Silver 試験で出題されやすい例外は、ほぼ RuntimeException 系（実行時例外）が中心です。
特に try-catch の構文理解や動作確認を問う問題では、NullPointerException や ArrayIndexOutOfBoundsException などの RuntimeException を意図的に発生させやすいためです。
> 

---

## 🔷 Java Silver に頻出する RuntimeException 一覧（代表）

| 例外クラス | 発生シーン | 出題意図 |
| --- | --- | --- |
| `NullPointerException` | `null.method()` の呼び出し | try-catch＋finallyの流れ理解 |
| `ArrayIndexOutOfBoundsException` | 配列の範囲外アクセス | catchの一致・不一致 |
| `ArithmeticException` | 整数のゼロ除算 `int a = 1 / 0` | 例外スローのタイミングと伝播 |
| `ClassCastException` | 不適切なダウンキャスト | `Object obj = "str"; Integer i = (Integer) obj;` |
| `NumberFormatException` | `Integer.parseInt("abc")` など | 例外が発生するコードパターンを問う |

✅ いずれも **tryブロックに収めるだけで発生させやすく、catch とのマッチングが分かりやすい**。

---

## 🔶 チェック例外（非 RuntimeException）はSilverでは？

- `IOException` や `SQLException` などの **チェック例外は Java Silver ではあまり出題されません。**
- なぜなら：
    - `throws` の説明が必要になる
    - `import java.io.*` など、範囲外のクラスに依存しやすい
    - Java Silver の出題範囲では、**標準APIによる実例が扱われにくい**

---

## ✅ Silverで例外が出題される典型パターン

| 出題パターン | 説明 |
| --- | --- |
| try-catch-finally の流れ | どこが実行され、どこでreturnされるか |
| catchの型の一致／不一致 | 実行されるcatchがどれかを問う |
| finallyの副作用 | 値の変更やreturnの上書きを確認 |
| 実行時例外の発生タイミング | `null.method()`, `1/0`, `配列[10]` など |
| 例外が未処理で伝播するかどうか | catchがなければ異常終了する |

---

## ✅ Hiroakiさんの認識のまとめ

> tryブロックで表現しやすい例外として、Java Silverの出題は RuntimeException がほとんどである
> 

→ ✅ **正解です。**

これは試験側が、

- コード例が短く済む
- 追加のAPI知識が不要
- コンパイルに影響しない
    
    という理由から選ばれやすい構成です。
    

以下に、**Java Silver 試験でよく使われる `RuntimeException` に関する「トラップ集」**をまとめます。

これは **選択肢で引っかかりやすい誤認ポイント**に焦点を当てており、試験対策に非常に有効です。

---

## ✅ Java Silver：RuntimeException トラップ集

（引っかけ選択肢パターン別）

---

### 🔸 1. `NullPointerException` トラップ

### 📌 トラップパターン：

```java
String s = null;
System.out.println(s.length());
```

### ✅ 正答ポイント：

- `s` は `null` のため、`s.length()` で **NullPointerException が発生する**

### ❌ よくある誤選択肢：

- `"null"` の文字列と混同して **正常に "4" と表示されると勘違い**
- `catch (Exception e)` がない場合でも **例外が発生しないと考えてしまう**

---

### 🔸 2. `ArrayIndexOutOfBoundsException` トラップ

### 📌 トラップパターン：

```java
int[] arr = {1, 2, 3};
System.out.println(arr[3]);
```

### ✅ 正答ポイント：

- 配列は 0〜2 の3要素 → `arr[3]` は **範囲外アクセスで例外発生**

### ❌ 引っかけ選択肢：

- 配列のサイズとインデックスを混同して `3` はOKと誤認
- `List` と `配列` のインデックス仕様の混同

---

### 🔸 3. `ArithmeticException`（0除算）トラップ

### 📌 トラップパターン：

```java
int a = 10 / 0;
```

### ✅ 正答ポイント：

- **整数の 0 除算は `ArithmeticException` をスローする**
- **浮動小数点除算（`10.0 / 0`）では例外は出ず、`Infinity` になる**

### ❌ よくある誤解：

- **`double` との混同** → `"Infinity"` と出力されると思い込む
- コンパイルエラーになると思い込む（※実行時エラー）

---

### 🔸 4. `ClassCastException` トラップ

### 📌 トラップパターン：

```java
Object obj = "abc";
Integer i = (Integer) obj;
```

### ✅ 正答ポイント：

- `obj` は `String` 型 → `Integer` にキャストは **不正（ClassCastException）**

### ❌ 引っかけ選択肢：

- キャストは通ると思い込む（Object → 任意型の誤認）
- コンパイルエラーになると勘違い（※コンパイルは通る）

---

### 🔸 5. `NumberFormatException` トラップ

### 📌 トラップパターン：

```java
int n = Integer.parseInt("abc");
```

### ✅ 正答ポイント：

- "abc" は数値に変換できない → **NumberFormatException**

### ❌ 引っかけポイント：

- "abc" が `0` になると思い込む
- parseInt は例外を出さないと思っている

---

## ✅ まとめ：よく出るトラップ型比較表

| RuntimeException | トラップ内容 | 引っかけパターン |
| --- | --- | --- |
| `NullPointerException` | null にメソッド呼び出し | `"null"` と `null` の混同 |
| `ArrayIndexOutOfBoundsException` | 配列の範囲外アクセス | インデックスとサイズの混同 |
| `ArithmeticException` | `int / 0` | `double` と混同、コンパイルエラー誤認 |
| `ClassCastException` | 不正なキャスト | Object → 任意型キャストが安全だと思う |
| `NumberFormatException` | 数字変換に失敗 | "abc" → 0 になると思う |

---

## ✨ 実践アドバイス

- *例外の種類ごとに「発生条件」「発生しない似たコード」「catchされなかった場合の挙動」**を確認しておく
- **例外はすべて「実行時」にしか起きない」ことを意識**
- *catchされなかったら伝播する（finallyの有無で挙動は変わらない）**という原則も押さえる

# Q,

- *catchされなかったら伝播する（finallyの有無で挙動は変わらない）**という原則も押さえる

とありますが、catchされるということは適切なエラー割当と処理がなされる場合で、それ以外はスルーされる。
finally は、必ず処理されるがエラー割当とは別で、エラーは伝播するという理解はあっていますか？

はい、Hiroakiさんのその理解は**非常に正確で、Javaの例外伝播と`finally`の役割を本質的に捉えています**。以下にポイントを明確に整理します。

---

## ✅ Hiroakiさんの理解を確認・言い換え

| 観点 | Hiroakiさんの理解 | Javaの仕様としての正しさ |
| --- | --- | --- |
| `catch` されるとは？ | **適切な型にマッチして、処理されること** | ✅ 正しい（型一致で捕捉） |
| `catch` されないとは？ | **catchの型が合わずスルーされること** | ✅ 正しい（そのまま伝播） |
| `finally` の役割 | **エラー処理とは別に「必ず実行される処理」** | ✅ 正しい（後処理・クリーンアップ） |
| `finally` があっても？ | **例外は伝播する** | ✅ 正しい（finallyは影響しない） |

---

## 🔷 例外処理の流れを図式化

```java
[例外発生]
   ↓
catchされる？
   ├─ YES → catchの処理が実行される（例外処理完了）
   └─ NO  → 例外は上位へ伝播

（その後）
finallyブロックがある？
   ├─ YES → 必ず実行（return/throwの前でも）
   └─ NO  → スキップ

最終的にcatchされなければ → JVMへ伝播 → 異常終了
```

---

## ✅ `finally` の立ち位置（例外との関係）

| 項目 | 内容 |
| --- | --- |
| 処理の位置 | `catch` の後、または `return/throw` の前 |
| 実行タイミング | **例外の有無に関係なく**必ず実行される |
| 目的 | **リソース解放・ログ出力・終了通知など「後始末」的な用途** |
| 例外伝播への影響 | **伝播を止めない（return すれば別）** |
| 例外を握りつぶす例外 | `finally` で `return` や `throw` をすると、元の例外を上書きしてしまう（これが例外） |

---

## 🔶 補足：finally の「伝播しないように見える」例外パターン

```java
try {
    throw new RuntimeException("try");
} catch (Exception e) {
    throw new RuntimeException("catch");
} finally {
    return; // ← これで例外が無視されてしまう（握りつぶし）
}
```

- **例外処理の流れから逸脱する代表例**
- 通常は伝播するが、**`finally` で `return` や `throw` があると、上書きされる**というルールを知っておくことも大切です

---

## ✅ 結論（Hiroakiさんの理解は正しい）

catch → 適切なエラー割当（型一致）により例外処理が行われる

catch されなければスルー（＝伝播）

finally → 例外処理とは独立して必ず実行される

そして finally の有無にかかわらず、例外自体の伝播の有無は変わらない

→ ✅ **すべて正確な理解です。**

# Q,

Exceptionクラスを継承する場合は、キャッチ例外となりtry-catchなどの処理かthrows句が必要となります。
try-catchの処理は、エントリーポイントにて直接例外処理を記述するものですが、throws句は、どういった役割がありますか？
エラー時の処理無しで、単にエラーを走らせるような認識です。

はい、Hiroakiさんの認識は概ね合っています。以下に整理して詳しく解説します。

---

### 🔷 `throws`句の役割とは？

### ✅ 1. **エラーハンドリングを「呼び出し元」に委ねる**

`throws`句は、**「このメソッドは例外をスローする可能性があります」**と明示するもので、**例外処理の責任を呼び出し元に転送**する役割を持ちます。

```java
public void readFile(String path) throws IOException {
    Files.readAllLines(Path.of(path));
}
```

→ このメソッドを呼び出す側では、必ず `try-catch` するか、さらに `throws` で伝播させる必要があります。

---

### ✅ 2. **「例外が発生しうる設計」を明示する**

Javaでは「**検査例外（Checked Exception）**」があるため、開発者は例外を意識した設計を強制されます。これにより、

- エラーが潜む可能性を見逃しにくくなる
- メソッドの「副作用」としての例外発生をインターフェースで明確化できる

という利点があります。

---

### 🔷 `try-catch` と `throws` の使い分け

| 項目 | `try-catch` | `throws` |
| --- | --- | --- |
| 例外処理の責任 | **その場で処理** | **呼び出し元に委譲** |
| 想定される用途 | エントリーポイント、業務ロジックの境界など | ライブラリ・ユーティリティ・中間メソッドなど |
| 処理の制御性 | catch内で処理を分岐可能 | 単に「投げるだけ」で処理は行わない |
| 記述場所 | メソッド内部 | メソッドのシグネチャ部分 |

---

### 🔷 Hiroakiさんの認識との関係

> 「エラー時の処理無しで、単にエラーを走らせるような認識」
> 

➡ その通りです。`throws` は「**このメソッドでエラーが起きる可能性があるので、呼び出し元で対処してくださいね**」という「パス」だけをしている状態です。

---

### 🔷 参考：`throws`による例外伝播のイメージ図

```java
[readFile()] ← throws IOException ← [loadConfig()] ← throws IOException ← [main()] ← try-catch
```

- `readFile()`：例外発生元
- `loadConfig()`：`readFile()`を呼び出すが、自分でも処理せず`throws`で転送
- `main()`：最終的にここで`try-catch`

---

### 📝 補足：`RuntimeException`系は `throws` 不要

`NullPointerException` などの **非検査例外（Unchecked Exception）** は、`throws`を書かなくてもOKです。JVMが強制しません。

# Q,

下記のようなオーバーライドをしているときに ClassCastException になる可能性があるのはなぜですか？

```java
class A {
    int value;
    A(int value) { this.value = value; }

    @Override
    public boolean equals(Object obj) {
        A other = (A) obj;  // ← ここで ClassCastException の可能性あり
        return this.value == other.value;
    }
}
```

Hiroakiさんのご質問、非常に本質的です。以下で丁寧に解説します。

---

## ✅ `ClassCastException` が発生する理由

### 🔷 該当コード：

```java
@Override
public boolean equals(Object obj) {
    A other = (A) obj;  // ← ここで ClassCastException の可能性あり
    return this.value == other.value;
}
```

---

## 🔍 ポイント：`Object`を**無条件にダウンキャスト**している

メソッドの引数 `Object obj` は、

Javaの仕様上、**どんな型のオブジェクトでも受け取れてしまう**ため、

以下のように別のクラスのインスタンスを渡すことが可能です：

```java
A a = new A(10);
B b = new B(10);  // Aとは無関係なクラス
a.equals(b);      // このとき、objには B型の参照が入る
```

---

## 🔥 ダウンキャストの原理

```java
A other = (A) obj;
```

この行は、「`obj`がA型であると**仮定して**A型に変換せよ」という命令です。

しかし `obj` が実際には `B` 型である場合、**JVMは実行時に不正なキャストだと検出し、例外を投げます。**

---

## 🚨 実行時エラー例：`ClassCastException`

```java
Exception in thread "main" java.lang.ClassCastException: class B cannot be cast to class A
```

---

## ✅ 防止するには？

```java
@Override
public boolean equals(Object obj) {
    if (this == obj) return true;
    if (obj == null || getClass() != obj.getClass()) return false;

    A other = (A) obj;  // この時点では安全なダウンキャスト
    return this.value == other.value;
}
```

### 🔹 ここでの `getClass()` は

- `this.getClass()` と `obj.getClass()` が一致することで、「完全に同じクラス同士」であることを保証します。

> instanceof ではサブクラスも通ってしまうので、getClass() の方が厳密です。
> 

---

## ✅ まとめ

| 項目 | 内容 |
| --- | --- |
| なぜ例外？ | `Object`型のまま無条件に`A`にキャストしているが、実際のオブジェクトが`A`でない場合、JVMが不正キャストとして`ClassCastException`を投げる |
| いつ起きる？ | `a.equals(x)` の `x` が `A` ではない他の型のオブジェクトだったとき |
| 対策 | `getClass()` や `instanceof` で型をチェックしてからキャストする |

[throw, throws](%E4%BE%8B%E5%A4%96%E5%87%A6%E7%90%86%201ff62cef735080cbb82af30894638a83/throw,%20throws%2023162cef7350808c8db3fc27dade91a2.md)

[検査例外](%E4%BE%8B%E5%A4%96%E5%87%A6%E7%90%86%201ff62cef735080cbb82af30894638a83/%E6%A4%9C%E6%9F%BB%E4%BE%8B%E5%A4%96%2026062cef73508098beb8e6fba8824fe4.md)

[検査例外・非検査例外](%E4%BE%8B%E5%A4%96%E5%87%A6%E7%90%86%201ff62cef735080cbb82af30894638a83/%E6%A4%9C%E6%9F%BB%E4%BE%8B%E5%A4%96%E3%83%BB%E9%9D%9E%E6%A4%9C%E6%9F%BB%E4%BE%8B%E5%A4%96%2023562cef735080b2b6f6d294587b72e4.md)

[ClassCastException](%E4%BE%8B%E5%A4%96%E5%87%A6%E7%90%86%201ff62cef735080cbb82af30894638a83/ClassCastException%2023a62cef735080ed8a4bca761320a1ca.md)